import { Component, ErrorInfo, ReactNode } from 'react';
import { Button } from './button';
import { AlertTriangle, RefreshCw } from 'lucide-react';

interface Props {
  children: ReactNode;
  fallback?: ReactNode;
}

interface State {
  hasError: boolean;
  error?: Error;
}

export class ErrorBoundary extends Component<Props, State> {
  constructor(props: Props) {
    super(props);
    this.state = { hasError: false };
  }

  static getDerivedStateFromError(error: Error): State {
    return { hasError: true, error };
  }

  componentDidCatch(error: Error, errorInfo: ErrorInfo) {
    console.error('Error caught by boundary:', error, errorInfo);
  }

  handleRetry = () => {
    this.setState({ hasError: false, error: undefined });
  };

  render() {
    if (this.state.hasError) {
      if (this.props.fallback) {
        return this.props.fallback;
      }

      return (
        <div className="flex flex-col items-center justify-center p-8 text-center">
          <div className="mb-4 rounded-full bg-destructive/10 p-4">
            <AlertTriangle className="h-8 w-8 text-destructive" />
          </div>
          <h2 className="mb-2 text-lg font-semibold">حدث خطأ غير متوقع</h2>
          <p className="mb-4 text-sm text-muted-foreground">
            نعتذر عن هذا الخطأ. يرجى المحاولة مرة أخرى.
          </p>
          <Button onClick={this.handleRetry} variant="outline" size="sm">
            <RefreshCw className="mr-2 h-4 w-4" />
            إعادة المحاولة
          </Button>
        </div>
      );
    }

    return this.props.children;
  }
}